Workbook

Sheet 人物卡
B2: 概念段 | AG2: 空白卡作者 | AJ2: 不咕鸟 | AO2: 联系方式 | AR2: QQ：1724745789
B3: 姓名 | D3: 望云 | G3: 性别 | I3: 男 | L3: 我出生在修仙世家，自幼因先天道体而被收入太玄门，天赋惊人，以雷法练气，因灵气逐渐凋零，而无法筑基，特此寻找其他方法 | Y3: 人物立绘
B4: 年龄 | D4: 16 | G4: 身高/体重 | I4: 184/65 | AG4: 更新记录
B5: 种族/国籍 | D5: 人 | G5: 语言 | I5: 通用语 | AG5: 1.1 | AH5: 增加了装备位，增加了检定预设中的其他加值来源
B6: 住址 | D6: 中国
B7: 外貌特征 | D7: 飘逸黑发，瘦高帅哥 | AG7: 1.2 | AH7: 增加了三豁免和特殊防御效果，补充了攻击预设中的附加成功
AG9: 1.3 | AH9: 增加了专长段，为部分区域增加了自动换行
B10: 性格个性 | D10: 冷酷谨慎机智
AG11: 1.4 | AH11: 将意志力和能量池单独提出来
AG13: 1.5 | AH13: 移除了检定预设，增加书签、天赋、缺陷和怪癖，增加了属性的完美加值
B14: 属性段 | AB14: 核算
C15: 属性 | E15: 属性总值 | G15: 检定总值 | I15: 传奇 | K15: 基础 | M15: 建卡 | O15: 购买 | Q15: 内在 | S15: 修行 | U15: 其他 | W15: 完美 | Y15: 检定加值 | AB15: 总属性点 | AD15: =SUM(M16:N24)+COUNTIF(M16:N24,5)-18 -> 12 | AG15: 1.6 | AH15: 修订了体型调整值的错误，增加了主动技能和其他文本信息的位置
B16: 生理 | C16: 力量 | E16: =SUM(K16,Q16:X16) -> 2 | G16: =SUM(E16,Y16) -> 2 | I16: =INT((E16-1)/5) -> 0 | K16: =SUM(M16:P16) -> 2 | M16: 2 | AB16: 总技能点 | AD16: =SUM(L28:M77)+COUNTIF(L28:M77,4)+2*COUNTIF(L28:M77,5) -> 20
C17: 敏捷 | E17: =SUM(K17,Q17:X17) -> 3 | G17: =SUM(E17,Y17) -> 3 | I17: =INT((E17-1)/5) -> 0 | K17: =SUM(M17:P17) -> 3 | M17: 3 | AB17: 总专长点 | AD17: =SUM(专长和其他文本信息!B4:C150) -> 0 | AG17: 1.7 | AH17: 修订了部分错误，修订了核算，令其更便于理解，增加了范围豁免
C18: 耐力 | E18: =SUM(K18,Q18:X18) -> 4 | G18: =SUM(E18,Y18) -> 4 | I18: =INT((E18-1)/5) -> 0 | K18: =SUM(M18:P18) -> 4 | M18: 4 | AB18: 属性点应为12
B19: 心智 | C19: 智力 | E19: =SUM(K19,Q19:X19) -> 4 | G19: =SUM(E19,Y19) -> 4 | I19: =INT((E19-1)/5) -> 0 | K19: =SUM(M19:P19) -> 4 | M19: 4 | AB19: 技能点应为20，若有特殊身份（2），技能点为22。 | AG19: 1.8 | AH19: 增加了专长名称，为技能部分重新排版，新增了装备负重计算
C20: 感知 | E20: =SUM(K20,Q20:X20) -> 5 | G20: =SUM(E20,Y20) -> 5 | I20: =INT((E20-1)/5) -> 0 | K20: =SUM(M20:P20) -> 4 | M20: 4 | S20: 1
C21: 决心 | E21: =SUM(K21,Q21:X21) -> 4 | G21: =SUM(E21,Y21) -> 4 | I21: =INT((E21-1)/5) -> 0 | K21: =SUM(M21:P21) -> 4 | M21: 4 | AG21: 1.9 | AH21: 属性段修订，将建卡属性与直接购买的属性分开，新增了防御总和。
B22: 互动 | C22: 风度 | E22: =SUM(K22,Q22:X22) -> 5 | G22: =SUM(E22,Y22) -> 5 | I22: =INT((E22-1)/5) -> 0 | K22: =SUM(M22:P22) -> 4 | M22: 4 | S22: 1
C23: 操控 | E23: =SUM(K23,Q23:X23) -> 2 | G23: =SUM(E23,Y23) -> 2 | I23: =INT((E23-1)/5) -> 0 | K23: =SUM(M23:P23) -> 2 | M23: 2 | AB23: 专长点应为15 | AG23: 1.1 | AH23: 新增常用检定，重写了能量池和刻度部分，重写了书签整备和主动技能。
C24: 沉着 | E24: =SUM(K24,Q24:X24) -> 3 | G24: =SUM(E24,Y24) -> 3 | I24: =INT((E24-1)/5) -> 0 | K24: =SUM(M24:P24) -> 3 | M24: 3 | AB24: 仅供参考
B26: 技能段
D27: 技能 | F27: 技能总值 | H27: 检定总值 | J27: 附加成功 | L27: 建卡 | N27: 检定加值 | P27: 专业 | V27: 升级来源 | X27: 升级来源 | Z27: 升级来源 | AB27: 升级来源 | AD27: 升级来源 | AF27: 升级来源 | AH27: 升级来源 | AJ27: 升级来源
B28: 生 理 | D28: 运动 | F28: =L28+COUNTA(V28:AK29) -> 2 | H28: =F28+N28 -> 2 | J28: =IF(F28>=5,INT((F28-3)/2),0) -> 0 | L28: 2
D30: 肉搏 | F30: =L30+COUNTA(V30:AK31) -> 0 | H30: =F30+N30 -> 0 | J30: =IF(F30>=5,INT((F30-3)/2),0) -> 0
D32: 驾驶 | F32: =L32+COUNTA(V32:AK33) -> 1 | H32: =F32+N32 -> 1 | J32: =IF(F32>=5,INT((F32-3)/2),0) -> 0 | L32: 1
D34: 枪械 | F34: =L34+COUNTA(V34:AK35) -> 0 | H34: =F34+N34 -> 0 | J34: =IF(F34>=5,INT((F34-3)/2),0) -> 0
D36: 手上功夫 | F36: =L36+COUNTA(V36:AK37) -> 0 | H36: =F36+N36 -> 0 | J36: =IF(F36>=5,INT((F36-3)/2),0) -> 0
D38: 隐藏 | F38: =L38+COUNTA(V38:AK39) -> 1 | H38: =F38+N38 -> 1 | J38: =IF(F38>=5,INT((F38-3)/2),0) -> 0 | L38: 1
D40: 求生 | F40: =L40+COUNTA(V40:AK41) -> 0 | H40: =F40+N40 -> 0 | J40: =IF(F40>=5,INT((F40-3)/2),0) -> 0
D42: 白刃 | F42: =L42+COUNTA(V42:AK43) -> 2 | H42: =F42+N42 -> 2 | J42: =IF(F42>=5,INT((F42-3)/2),0) -> 0 | L42: 2
B44: 心 智 | D44: 学识 | F44: =L44+COUNTA(V44:AK45) -> 1 | H44: =F44+N44 -> 1 | J44: =IF(F44>=5,INT((F44-3)/2),0) -> 0 | L44: 1
D46: 电脑 | F46: =L46+COUNTA(V46:AK47) -> 0 | H46: =F46+N46 -> 0 | J46: =IF(F46>=5,INT((F46-3)/2),0) -> 0
D48: 调查 | F48: =L48+COUNTA(V48:AK49) -> 0 | H48: =F48+N48 -> 0 | J48: =IF(F48>=5,INT((F48-3)/2),0) -> 0
D50: 医学 | F50: =L50+COUNTA(V50:AK51) -> 0 | H50: =F50+N50 -> 0 | J50: =IF(F50>=5,INT((F50-3)/2),0) -> 0
D52: 神秘学 | F52: =L52+COUNTA(V52:AK53) -> 4 | H52: =F52+N52 -> 4 | J52: =IF(F52>=5,INT((F52-3)/2),0) -> 0 | L52: 4
D54: 科学 | F54: =L54+COUNTA(V54:AK55) -> 2 | H54: =F54+N54 -> 2 | J54: =IF(F54>=5,INT((F54-3)/2),0) -> 0 | L54: 2
D56: 手艺 | F56: =L56+COUNTA(V56:AK57) -> 0 | H56: =F56+N56 -> 0 | J56: =IF(F56>=5,INT((F56-3)/2),0) -> 0
D58: 手艺 | F58: =L58+COUNTA(V58:AK59) -> 0 | H58: =F58+N58 -> 0 | J58: =IF(F58>=5,INT((F58-3)/2),0) -> 0
B60: 互 动 | D60: 动物沟通 | F60: =L60+COUNTA(V60:AK61) -> 0 | H60: =F60+N60 -> 0 | J60: =IF(F60>=5,INT((F60-3)/2),0) -> 0
...

Sheet 专长和其他文本信息
B2: 专长段 | X2: 主干资源
B3: 专长等级 | D3: 专长名称 | F3: 专长内容（请将同一专长的不同等级分开填写） | X3: 血统 | AD3: 改造 | AJ3: 瞳术
B4: 、1 | D4: 、生命潜力 | F4: 、 1级：前提：需求耐力4，风度4。生命拥有进化的潜力，而你在他们之中也是最特别的那个。你在进行本能觉醒的开启检定时，检定结果增加1点。
X5: 魔导书 | AD5: 修炼体系 | AF5: 上清神霄感应雷法真传 | AJ5: 其他
X7: 其他 | AD7: 其他 | AJ7: 其他
X9: 称号 | AD9: 称号 | AJ9: 称号
X11: 流派 | AD11: 流派 | AJ11: 流派
X14: 被动特性
X15: 特性名 | Z15: 特性内容
X16: 上清神霄感应雷法真传 | Z16: 上清神霄感应雷法真传（下简称“上清雷法”）为轮回之境萃取修真宇宙观多种雷法，总合而成之雷法真传，藉由吞吐天地元气，淬炼道心，天人合一，超脱长生。 雷法乃总摄天地阴阳震荡之意。 【天道永恒，无善无恶，无常无非常，不可道，是名为道。修真界通常有三种因应态度。雷法修行代表的顺天而行，拳修代表的自身圆满，剑修代表的逆天而为。雷法修行者顺应天意，最终与天道合一，天道即为我心，随心所欲而不逾矩。拳修自身即成宇宙，自成体系，万法自足，求诸身内。剑修则逆天而行，斩破一切束缚，唯心为剑，劈空见性，逍遥快意。皆可长生久视，成造化主。】 =========================================================================================================== 兑换提示：雷电系修真，核心加强【雷】关键词的道术。 其兑换以“掌心雷”作为核心，几乎所有兑换全部围绕该技能作为强化，资源极其集中，效果也极其明显。 总体而言可玩性较强，作为一种特定的输出非常适合，而且画风满满。 重点是核心的兑换部分也不是很贵，可以在前期早早成形。 缺点其大部分的强化都是被动加强“掌心雷”，所以一旦“掌心雷”无法使用则兑换整体废掉，并且这些被动技能无法使用书签，所以自身资源非常集中。
X19: 上清雷法第一层 | Z19: 技能树：开启上清雷法D级技能树 能量池：真气 特殊：无 特性：雷修（双特性），天雷锻体 描述：修习雷法之人，有较高心性道德要求。在一般修真或东方古代世界中，雷法修行者被视为正派。在一般普世魔法世界中，雷法可能被视同为同级的神圣系魔法。 雷修：你获得相当于上清雷法支线等级的道术施法者职能，可以用来学习和施展通用道术，你获得道力能量池。 天雷锻体：你获得2点全能量抗力。
X22: 掌心雷 | Z22: 关键字：【雷】 专业：道术 威力值：2 价格：500 动作：标准动作 能耗： 成分：语言，姿势 射程：20米 目标：一个目标 范围：无 持续：立即 描述：掌心雷攻击声音很大，相当于雷声的程度，这意味着方圆百里范围内所有具备听力的目标都会听到你的攻击。 效果：你以道术施法检定进行一次远程攻击，该次远程攻击的武器伤害为本道术的道术威力值，造成雷电严重伤害。 研发：你可以花费9XP进行研发，研发后获得以下效果： 本道术能耗变为1点，威力值提升为2点，之后本道术可以如常升阶。 然后你的本次攻击获得2点附加成功，射程改为20米。
Z28: 口头禅 +2 XP 删除 战斗每轮1D10，出1则浪费迅捷动作。 想象力丰富 +2 XP 删除 任务未提5个建议，全检定-2DP。 晕车/船 +2 XP 删除 乘坐机械载具时获得5点不可叠加的恶心点数。短休消除。 上瘾 +2 XP 删除 上瘾速度快，发作周期减半，禁断症状豁免-6DP。 爱出风头 +2 XP 删除 唬骗/易容/躲藏-3DP，战斗中总是第一个站出来。 C. 缺陷与天赋 (FLAWS & TALENTS)
Z31: 空气朋友 LV.-2 +2 点 删除 所有人对你互动获2DP完美加值。 养啥死啥 LV.-1 +1 点 删除 非人宠物必死。 音痴 LV.-2 +2 点 删除 歌唱/演奏自动失败。 好奇心 LV.-1 +1 点 删除 不去探索未知则全检定-2DP。 机械白痴 LV.-4 +4 点 删除 使用科技物品D10判故障。
Z34: 夜视 -1 点 删除 获得黑暗视觉。 幸运 -1 点 删除 检定双判取高 (次数限制)。 快速康复 -1 点 删除 自然恢复速度翻倍。 灵感 -1 点 删除 直觉检定+5附加，首次免投。 战斗反射 -1 点 删除 措手不及仍可用反射动作。

Sheet 意志力与能量池
B2: 意志力
B3: 总上限 | D3: 其他需要记录的填这里
B4: =人物卡!D87 -> 7
B5: 总加值 | D5: 初始 | F5: 传奇风度 | H5: 来源 | J5: 来源 | L5: 来源 | N5: 来源 | P5: 来源 | R5: 来源 | T5: 来源 | V5: 来源 | X5: 来源 | Z5: 来源 | AB5: 来源 | AD5: 来源 | AF5: 来源 | AH5: 来源 | AJ5: 来源
B6: =SUM(D6:AK6) -> 3 | D6: 3 | F6: =人物卡!I22*2 -> 0
B7: 恢复方式 | D7: 每进行一次至少1小时的短休息（不能做其他行动），恢复1点意志力。 每进行至少8小时的长休息（不进行任何行动，而是用于睡眠之类），人物可以投掷1D10，这不是一次检定，恢复该投骰结果+传奇决心+传奇沉着/点意志力。
B9: 基础用法 | D9: 人物在进行一个行动时（无论回合外还是回合内），若该行动不是周期性行为且只需一次检定（包括并不限于攻击、技能判定、对抗、防御等）可以无需任何动作直接支付1点意志力，在该行动上获得3DP的完美加值，这种用法对一次行动只能使用一次。 或者人物在受到攻击时，可以支付1点意志力，针对该次攻击人物在防御上获得3点完美加值。 当人物因伤势过重而昏迷时，可以花费1点意志力使昏迷延后。若为战斗时，则每1点意志力可以使人物继续行动1轮，每轮结束时决定是否花费该意志力，若不花费，则该轮结束后立即昏迷。若为非战斗时，则每1点意志力可以使人物继续行动1分钟。在持续时间内，人物不会因为伤势过重而昏迷。
B16: 能量池
B17: 能量池名称 | D17: 能量池分类 | F17: 其他需要记录的填这里
B18: 道力 | D18: 魔幻本质
B19: 能量池上限 | D19: 来源 | F19: 来源 | H19: 来源 | J19: 来源 | L19: 来源 | N19: 来源 | P19: 来源 | R19: 来源 | T19: 来源 | V19: 来源 | X19: 来源 | Z19: 来源 | AB19: 来源 | AD19: 来源 | AF19: 来源 | AH19: 来源 | AJ19: 来源
B20: 10
B21: 恢复方式 | D21: 冥想4小时+1D6+传奇决心，短休1小时+1点
B23: 基础用法 | D23: ①掌心雷1点/次 ②雷铠1点/分钟
B30: 刻度
B31: 刻度名称 | D31: 刻度上限 | F31: 初始刻度 | H31: 其他需要记录的填这里
B32: 天雷蓄能 | D32: 3层
B33: 恢复方式 | D33: 每施放1次雷法+1层
B37: 基础用法 | D37: 满3层后，下次雷法附加成功+1
B44: 如果有多个能量池或刻度，则可以复制上述格式并在本页粘贴
C46: 能量池
C47: 能量池名称 | E47: 能量池分类 | G47: 其他需要记录的填这里
C48: 真气 | E48: 魔幻本质
C49: 能量池上限 | E49: 来源 | G49: 来源 | I49: 来源 | K49: 来源 | M49: 来源 | O49: 来源 | Q49: 来源 | S49: 来源 | U49: 来源 | W49: 来源 | Y49: 来源 | AA49: 来源 | AC49: 来源 | AE49: 来源 | AG49: 来源 | AI49: 来源 | AK49: 来源
C50: 9
C51: 恢复方式 | E51: 长休的时候自动回满，短休的时候可以打坐进行感知+决心检定，每有1点成功数可以恢复1点真气
C53: 基础用法 | E53: 当你进行三豁免检定时，花费1点真气，该检定获得1DP能量加值。对您而言: 这意味着您在进行意志豁免、反射豁免、强韧豁免时，可以消耗1点【真气】，让您的豁免检定投骰时多加1个骰子（1DP）"

Sheet 攻击预设
B2: 近战肉搏攻击：力量+肉搏技能等级+天生武器伤害值±相关调整值 | T2: 伤害上限为=力量+肉搏技能等级+天生武器伤害值
B3: 近战白刃攻击：力量+白刃技能等级+武器伤害值±相关调整值 | T3: 伤害上限为=力量+白刃技能等级+武器伤害值
B4: 轻武器投掷攻击：敏捷+运动技能等级+武器伤害±相关调整值 | T4: 伤害上限为=运动技能等级+武器伤害值*2
B5: 重武器投掷攻击：力量+运动技能等级+武器伤害±相关调整值 | T5: 伤害上限为=运动技能等级+武器伤害值*2
B6: 远程弓箭攻击：敏捷+运动技能等级+武器伤害±相关调整值 | T6: 伤害上限为=该武器的力量需求+运动技能等级+武器伤害*2
B7: 远程枪械攻击：敏捷+枪械技能等级+武器伤害±相关调整值 | T7: 伤害上限为=枪械技能等级+武器伤害*2
B8: 远程炮类攻击：智力+枪械技能等级+武器伤害±相关调整值 | T8: 伤害上限为=枪械技能等级+武器伤害*2
B10: 攻击方式： | E10: 掌心雷
B11: 总DP | D11: 属性 | F11: 技能 | H11: 武器 | J11: 专业 | L11: 其他 | N11: 其他 | P11: 其他 | R11: 其他 | T11: 其他 | V11: 其他 | X11: 其他 | Z11: 其他 | AB11: 其他 | AD11: 其他 | AF11: 其他 | AH11: 其他 | AJ11: 其他 | AL11: 其他 | AN11: 其他 | AP11: 其他 | AR11: 其他 | AT11: 其他 | AV11: 其他 | AX11: 其他
B12: 12
B13: 伤害上限 | D13: 属性 | F13: 技能 | H13: 武器 | J13: 其他 | L13: 其他 | N13: 其他 | P13: 其他 | R13: 其他 | T13: 其他 | V13: 其他 | X13: 其他 | Z13: 其他 | AB13: 其他 | AD13: 其他 | AF13: 其他 | AH13: 其他 | AJ13: 其他 | AL13: 其他 | AN13: 其他 | AP13: 其他 | AR13: 其他 | AT13: 其他 | AV13: 其他 | AX13: 其他
B14: 2
B15: 附加成功 | D15: 传奇属性 | F15: 技能附加 | H15: 其他 | J15: 其他 | L15: 其他 | N15: 其他 | P15: 其他 | R15: 其他 | T15: 其他 | V15: 其他 | X15: 其他 | Z15: 其他 | AB15: 其他 | AD15: 其他 | AF15: 其他 | AH15: 其他 | AJ15: 其他 | AL15: 其他 | AN15: 其他 | AP15: 其他 | AR15: 其他 | AT15: 其他 | AV15: 其他 | AX15: 其他
B16: =SUM(D16:AY16) -> 0
B17: 攻击特殊属性 | D17: 高速 | F17: 破甲 | H17: 破魔 | J17: 加骰 | L17: 其他关键词 | N17: 其他关键词 | P17: 其他关键词 | R17: 其他关键词 | T17: 其他关键词 | V17: 其他关键词 | X17: 其他关键词 | Z17: 其他关键词 | AB17: 其他关键词 | AD17: 其他关键词 | AF17: 其他关键词 | AH17: 其他关键词 | AJ17: 其他关键词 | AL17: 其他关键词 | AN17: 其他关键词 | AP17: 其他关键词 | AR17: 其他关键词 | AT17: 其他关键词 | AV17: 其他关键词 | AX17: 其他关键词
B19: 消耗 | D19: 意志力 | F19: 能量 | H19: 能量 | J19: 能量 | L19: 能量 | N19: 能量 | P19: 能量 | R19: 能量 | T19: 能量 | V19: 能量 | X19: 能量 | Z19: 能量 | AB19: 能量 | AD19: 能量 | AF19: 能量 | AH19: 能量 | AJ19: 能量 | AL19: 能量 | AN19: 能量 | AP19: 能量 | AR19: 能量 | AT19: 能量 | AV19: 能量 | AX19: 能量
D20: 0 | F20: 1
B21: 动作 | D21: 姿势 | F21: 射程 | H21: 20 | J21: 范围 | L21: 无
B22: 其他效果
B26: 攻击方式：
B27: 总DP | D27: 属性 | F27: 技能 | H27: 武器 | J27: 专业 | L27: 其他 | N27: 其他 | P27: 其他 | R27: 其他 | T27: 其他 | V27: 其他 | X27: 其他 | Z27: 其他 | AB27: 其他 | AD27: 其他 | AF27: 其他 | AH27: 其他 | AJ27: 其他 | AL27: 其他 | AN27: 其他 | AP27: 其他 | AR27: 其他 | AT27: 其他 | AV27: 其他 | AX27: 其他
B28: =SUM(D28:AY28) -> 0
B29: 伤害上限 | D29: 属性 | F29: 技能 | H29: 武器 | J29: 其他 | L29: 其他 | N29: 其他 | P29: 其他 | R29: 其他 | T29: 其他 | V29: 其他 | X29: 其他 | Z29: 其他 | AB29: 其他 | AD29: 其他 | AF29: 其他 | AH29: 其他 | AJ29: 其他 | AL29: 其他 | AN29: 其他 | AP29: 其他 | AR29: 其他 | AT29: 其他 | AV29: 其他 | AX29: 其他
B30: =SUM(D30:AY30) -> 0
B31: 附加成功 | D31: 传奇属性 | F31: 技能附加 | H31: 其他 | J31: 其他 | L31: 其他 | N31: 其他 | P31: 其他 | R31: 其他 | T31: 其他 | V31: 其他 | X31: 其他 | Z31: 其他 | AB31: 其他 | AD31: 其他 | AF31: 其他 | AH31: 其他 | AJ31: 其他 | AL31: 其他 | AN31: 其他 | AP31: 其他 | AR31: 其他 | AT31: 其他 | AV31: 其他 | AX31: 其他
B32: =SUM(D32:AY32) -> 0
B33: 攻击特殊属性 | D33: 高速 | F33: 破甲 | H33: 破魔 | J33: 加骰 | L33: 其他关键词 | N33: 其他关键词 | P33: 其他关键词 | R33: 其他关键词 | T33: 其他关键词 | V33: 其他关键词 | X33: 其他关键词 | Z33: 其他关键词 | AB33: 其他关键词 | AD33: 其他关键词 | AF33: 其他关键词 | AH33: 其他关键词 | AJ33: 其他关键词 | AL33: 其他关键词 | AN33: 其他关键词 | AP33: 其他关键词 | AR33: 其他关键词 | AT33: 其他关键词 | AV33: 其他关键词 | AX33: 其他关键词
B35: 消耗 | D35: 意志力 | F35: 能量 | H35: 能量 | J35: 能量 | L35: 能量 | N35: 能量 | P35: 能量 | R35: 能量 | T35: 能量 | V35: 能量 | X35: 能量 | Z35: 能量 | AB35: 能量 | AD35: 能量 | AF35: 能量 | AH35: 能量 | AJ35: 能量 | AL35: 能量 | AN35: 能量 | AP35: 能量 | AR35: 能量 | AT35: 能量 | AV35: 能量 | AX35: 能量
B37: 动作 | F37: 射程 | J37: 范围
B38: 其他效果
B42: 攻击方式：
B43: 总DP | D43: 属性 | F43: 技能 | H43: 武器 | J43: 专业 | L43: 其他 | N43: 其他 | P43: 其他 | R43: 其他 | T43: 其他 | V43: 其他 | X43: 其他 | Z43: 其他 | AB43: 其他 | AD43: 其他 | AF43: 其他 | AH43: 其他 | AJ43: 其他 | AL43: 其他 | AN43: 其他 | AP43: 其他 | AR43: 其他 | AT43: 其他 | AV43: 其他 | AX43: 其他
B44: =SUM(D44:AY44) -> 0
B45: 伤害上限 | D45: 属性 | F45: 技能 | H45: 武器 | J45: 其他 | L45: 其他 | N45: 其他 | P45: 其他 | R45: 其他 | T45: 其他 | V45: 其他 | X45: 其他 | Z45: 其他 | AB45: 其他 | AD45: 其他 | AF45: 其他 | AH45: 其他 | AJ45: 其他 | AL45: 其他 | AN45: 其他 | AP45: 其他 | AR45: 其他 | AT45: 其他 | AV45: 其他 | AX45: 其他
B46: =SUM(D46:AY46) -> 0
B47: 附加成功 | D47: 传奇属性 | F47: 技能附加 | H47: 其他 | J47: 其他 | L47: 其他 | N47: 其他 | P47: 其他 | R47: 其他 | T47: 其他 | V47: 其他 | X47: 其他 | Z47: 其他 | AB47: 其他 | AD47: 其他 | AF47: 其他 | AH47: 其他 | AJ47: 其他 | AL47: 其他 | AN47: 其他 | AP47: 其他 | AR47: 其他 | AT47: 其他 | AV47: 其他 | AX47: 其他
B48: =SUM(D48:AY48) -> 0
B49: 攻击特殊属性 | D49: 高速 | F49: 破甲 | H49: 破魔 | J49: 加骰 | L49: 其他关键词 | N49: 其他关键词 | P49: 其他关键词 | R49: 其他关键词 | T49: 其他关键词 | V49: 其他关键词 | X49: 其他关键词 | Z49: 其他关键词 | AB49: 其他关键词 | AD49: 其他关键词 | AF49: 其他关键词 | AH49: 其他关键词 | AJ49: 其他关键词 | AL49: 其他关键词 | AN49: 其他关键词 | AP49: 其他关键词 | AR49: 其他关键词 | AT49: 其他关键词 | AV49: 其他关键词 | AX49: 其他关键词
B51: 消耗 | D51: 意志力 | F51: 能量 | H51: 能量 | J51: 能量 | L51: 能量 | N51: 能量 | P51: 能量 | R51: 能量 | T51: 能量 | V51: 能量 | X51: 能量 | Z51: 能量 | AB51: 能量 | AD51: 能量 | AF51: 能量 | AH51: 能量 | AJ51: 能量 | AL51: 能量 | AN51: 能量 | AP51: 能量 | AR51: 能量 | AT51: 能量 | AV51: 能量 | AX51: 能量
B53: 动作 | F53: 射程 | J53: 范围
...

Sheet 常用检定
B2: 常用检定
B3: 心灵检定 | D3: 总值 | F3: 决心 | H3: 沉着 | J3: 其他 | L3: 其他 | N3: 其他 | P3: 其他 | R3: 其他 | T3: 黑客入侵检定 | V3: 总值 | X3: 智力 | Z3: 电脑 | AB3: 专业 | AD3: 其他 | AF3: 其他 | AH3: 其他 | AJ3: 其他
D4: =SUM(F4:S4) -> 7 | F4: =人物卡!G21 -> 4 | H4: =人物卡!G24 -> 3 | V4: =SUM(X4:AK4) -> 4 | X4: =人物卡!G19 -> 4 | Z4: =人物卡!H46 -> 0
D5: 总附加成功 | F5: 传奇决心 | H5: 传奇沉着 | J5: 其他 | L5: 其他 | N5: 其他 | P5: 其他 | R5: 其他 | V5: 总附加成功 | X5: 传奇智力 | Z5: 电脑附加 | AB5: 其他 | AD5: 其他 | AF5: 其他 | AH5: 其他 | AJ5: 其他
D6: =SUM(F6:S6) -> 0 | F6: =人物卡!I21 -> 0 | H6: =人物卡!I24 -> 0 | V6: =SUM(X6:AK6) -> 0 | X6: =人物卡!I19 -> 0 | Z6: =人物卡!J46 -> 0
B7: 侦查检定 | D7: 总值 | F7: 感知 | H7: 调查 | J7: 专业 | L7: 其他 | N7: 其他 | P7: 其他 | R7: 其他 | T7: 急救检定 | V7: 总值 | X7: 敏捷 | Z7: 医学 | AB7: 专业 | AD7: 其他 | AF7: 其他 | AH7: 其他 | AJ7: 其他
D8: =SUM(F8:S8) -> 5 | F8: =人物卡!G20 -> 5 | H8: =人物卡!H48 -> 0 | V8: =SUM(X8:AK8) -> 3 | X8: =人物卡!G17 -> 3 | Z8: =人物卡!H50 -> 0
D9: 总附加成功 | F9: 传奇感知 | H9: 调查附加 | J9: 其他 | L9: 其他 | N9: 其他 | P9: 其他 | R9: 其他 | V9: 总附加成功 | X9: 传奇敏捷 | Z9: 医学附加 | AB9: 其他 | AD9: 其他 | AF9: 其他 | AH9: 其他 | AJ9: 其他
D10: =SUM(F10:S10) -> 0 | F10: =人物卡!I20 -> 0 | H10: =人物卡!J48 -> 0 | V10: =SUM(X10:AK10) -> 0 | X10: =人物卡!I17 -> 0 | Z10: =人物卡!J50 -> 0
B11: 搜索检定 | D11: 总值 | F11: 智力 | H11: 调查 | J11: 专业 | L11: 其他 | N11: 其他 | P11: 其他 | R11: 其他 | T11: 诊断检定 | V11: 总值 | X11: 智力 | Z11: 医学 | AB11: 专业 | AD11: 其他 | AF11: 其他 | AH11: 其他 | AJ11: 其他
D12: =SUM(F12:S12) -> 4 | F12: =人物卡!G19 -> 4 | H12: =人物卡!H48 -> 0 | V12: =SUM(X12:AK12) -> 4 | X12: =人物卡!G19 -> 4 | Z12: =人物卡!H50 -> 0
D13: 总附加成功 | F13: 传奇智力 | H13: 调查附加 | J13: 其他 | L13: 其他 | N13: 其他 | P13: 其他 | R13: 其他 | V13: 总附加成功 | X13: 传奇智力 | Z13: 医学附加 | AB13: 其他 | AD13: 其他 | AF13: 其他 | AH13: 其他 | AJ13: 其他
D14: =SUM(F14:S14) -> 0 | F14: =人物卡!I19 -> 0 | H14: =人物卡!J48 -> 0 | V14: =SUM(X14:AK14) -> 0 | X14: =人物卡!I19 -> 0 | Z14: =人物卡!J50 -> 0
B15: 聆听检定 | D15: 总值 | F15: 感知 | H15: 调查 | J15: 专业 | L15: 其他 | N15: 其他 | P15: 其他 | R15: 其他 | T15: 治疗检定 | V15: 总值 | X15: 智力 | Z15: 医学 | AB15: 专业 | AD15: 其他 | AF15: 其他 | AH15: 其他 | AJ15: 其他
D16: =SUM(F16:S16) -> 5 | F16: =人物卡!G20 -> 5 | H16: =人物卡!H48 -> 0 | V16: =SUM(X16:AK16) -> 4 | X16: =人物卡!G19 -> 4 | Z16: =人物卡!H50 -> 0
D17: 总附加成功 | F17: 传奇感知 | H17: 调查附加 | J17: 其他 | L17: 其他 | N17: 其他 | P17: 其他 | R17: 其他 | V17: 总附加成功 | X17: 传奇智力 | Z17: 医学附加 | AB17: 其他 | AD17: 其他 | AF17: 其他 | AH17: 其他 | AJ17: 其他
D18: =SUM(F18:S18) -> 0 | F18: =人物卡!I20 -> 0 | H18: =人物卡!J48 -> 0 | V18: =SUM(X18:AK18) -> 0 | X18: =人物卡!I19 -> 0 | Z18: =人物卡!J50 -> 0
B19: 躲藏检定 | D19: 总值 | F19: 敏捷 | H19: 隐藏 | J19: 专业 | L19: 其他 | N19: 其他 | P19: 其他 | R19: 其他 | T19: 法术辨识检定 | V19: 总值 | X19: 智力 | Z19: 神秘学 | AB19: 专业 | AD19: 其他 | AF19: 其他 | AH19: 其他 | AJ19: 其他
D20: =SUM(F20:S20) -> 4 | F20: =人物卡!G17 -> 3 | H20: =人物卡!H38 -> 1 | V20: =SUM(X20:AK20) -> 8 | X20: =人物卡!G19 -> 4 | Z20: =人物卡!H52 -> 4
D21: 总附加成功 | F21: 传奇敏捷 | H21: 隐藏附加 | J21: 其他 | L21: 其他 | N21: 其他 | P21: 其他 | R21: 其他 | V21: 总附加成功 | X21: 传奇智力 | Z21: 神秘学附加 | AB21: 其他 | AD21: 其他 | AF21: 其他 | AH21: 其他 | AJ21: 其他
D22: =SUM(F22:S22) -> 0 | F22: =人物卡!I17 -> 0 | H22: =人物卡!J38 -> 0 | V22: =SUM(X22:AK22) -> 0 | X22: =人物卡!I19 -> 0 | Z22: =人物卡!J52 -> 0
B23: 闯越检定 | D23: 总值 | F23: 力量/敏捷 | H23: 运动 | J23: 专业 | L23: 其他 | N23: 其他 | P23: 其他 | R23: 其他 | T23: 威吓检定 | V23: 总值 | X23: 操控 | Z23: 胁迫 | AB23: 专业 | AD23: 其他 | AF23: 其他 | AH23: 其他 | AJ23: 其他
D24: =SUM(F24:S24) -> 5 | F24: =MAX(人物卡!G16,人物卡!G17) -> 3 | H24: =人物卡!H28 -> 2 | V24: =SUM(X24:AK24) -> 2 | X24: =人物卡!G23 -> 2 | Z24: =人物卡!H64 -> 0
D25: 总附加成功 | F25: 传奇力量/敏捷 | H25: 运动附加 | J25: 其他 | L25: 其他 | N25: 其他 | P25: 其他 | R25: 其他 | V25: 总附加成功 | X25: 传奇操控 | Z25: 胁迫附加 | AB25: 其他 | AD25: 其他 | AF25: 其他 | AH25: 其他 | AJ25: 其他
D26: =SUM(F26:S26) -> 0 | F26: =MAX(人物卡!I16,人物卡!I17) -> 0 | H26: =人物卡!J28 -> 0 | V26: =SUM(X26:AK26) -> 0 | X26: =人物卡!I23 -> 0 | Z26: =人物卡!J64 -> 0
B27: 平衡感检定 | D27: 总值 | F27: 敏捷 | H27: 运动 | J27: 专业 | L27: 其他 | N27: 其他 | P27: 其他 | R27: 其他 | T27: 说服检定 | V27: 总值 | X27: 操控 | Z27: 交际 | AB27: 专业 | AD27: 其他 | AF27: 其他 | AH27: 其他 | AJ27: 其他
D28: =SUM(F28:S28) -> 5 | F28: =人物卡!G17 -> 3 | H28: =人物卡!H28 -> 2 | V28: =SUM(X28:AK28) -> 4 | X28: =人物卡!G23 -> 2 | Z28: =人物卡!H66 -> 2
D29: 总附加成功 | F29: 传奇敏捷 | H29: 运动附加 | J29: 其他 | L29: 其他 | N29: 其他 | P29: 其他 | R29: 其他 | V29: 总附加成功 | X29: 传奇操控 | Z29: 交际附加 | AB29: 其他 | AD29: 其他 | AF29: 其他 | AH29: 其他 | AJ29: 其他
D30: =SUM(F30:S30) -> 0 | F30: =人物卡!I17 -> 0 | H30: =人物卡!J28 -> 0 | V30: =SUM(X30:AK30) -> 0 | X30: =人物卡!I23 -> 0 | Z30: =人物卡!J66 -> 0
B31: 追踪检定 | D31: 总值 | F31: 感知 | H31: 求生 | J31: 专业 | L31: 其他 | N31: 其他 | P31: 其他 | R31: 其他 | T31: 唬骗检定 | V31: 总值 | X31: 操控 | Z31: 掩饰 | AB31: 专业 | AD31: 其他 | AF31: 其他 | AH31: 其他 | AJ31: 其他
D32: =SUM(F32:S32) -> 5 | F32: =人物卡!G20 -> 5 | H32: =人物卡!H40 -> 0 | V32: =SUM(X32:AK32) -> 2 | X32: =人物卡!G23 -> 2 | Z32: =人物卡!H68 -> 0
D33: 总附加成功 | F33: 传奇感知 | H33: 求生附加 | J33: 其他 | L33: 其他 | N33: 其他 | P33: 其他 | R33: 其他 | V33: 总附加成功 | X33: 传奇操控 | Z33: 掩饰附加 | AB33: 其他 | AD33: 其他 | AF33: 其他 | AH33: 其他 | AJ33: 其他
D34: =SUM(F34:S34) -> 0 | F34: =人物卡!I20 -> 0 | H34: =人物卡!J40 -> 0 | V34: =SUM(X34:AK34) -> 0 | X34: =人物卡!I23 -> 0 | Z34: =人物卡!J68 -> 0
B35: 文件解读检定 | D35: 总值 | F35: 智力 | H35: 学识 | J35: 专业 | L35: 其他 | N35: 其他 | P35: 其他 | R35: 其他 | T35: 易容检定 | V35: 总值 | X35: 智力/操控 | Z35: 掩饰 | AB35: 专业 | AD35: 其他 | AF35: 其他 | AH35: 其他 | AJ35: 其他
D36: =SUM(F36:S36) -> 5 | F36: =人物卡!G19 -> 4 | H36: =人物卡!H44 -> 1 | V36: =SUM(X36:AK36) -> 4 | X36: =MAX(人物卡!G19,人物卡!G23) -> 4 | Z36: =人物卡!H72 -> 0
D37: 总附加成功 | F37: 传奇智力 | H37: 学识附加 | J37: 其他 | L37: 其他 | N37: 其他 | P37: 其他 | R37: 其他 | V37: 总附加成功 | X37: 传奇智力/操控 | Z37: 掩饰附加 | AB37: 其他 | AD37: 其他 | AF37: 其他 | AH37: 其他 | AJ37: 其他
D38: =SUM(F38:S38) -> 0 | F38: =人物卡!I19 -> 0 | H38: =人物卡!J44 -> 0 | V38: =SUM(X38:AK38) -> 0 | X38: =MAX(人物卡!I19,人物卡!I23) -> 0 | Z38: =人物卡!J72 -> 0
B39: 怪物知识检定 | D39: 总值 | F39: 智力 | H39: 学识 | J39: 专业 | L39: 其他 | N39: 其他 | P39: 其他 | R39: 其他 | T39: 伪装检定 | V39: 总值 | X39: 智力/操控 | Z39: 掩饰 | AB39: 专业 | AD39: 其他 | AF39: 其他 | AH39: 其他 | AJ39: 其他
D40: =SUM(F40:S40) -> 5 | F40: =人物卡!G19 -> 4 | H40: =人物卡!H44 -> 1 | V40: =SUM(X40:AK40) -> 4 | X40: =MAX(人物卡!G19,人物卡!G23) -> 4 | Z40: =人物卡!H76 -> 0
D41: 总附加成功 | F41: 传奇智力 | H41: 学识附加 | J41: 其他 | L41: 其他 | N41: 其他 | P41: 其他 | R41: 其他 | V41: 总附加成功 | X41: 传奇智力/操控 | Z41: 掩饰附加 | AB41: 其他 | AD41: 其他 | AF41: 其他 | AH41: 其他 | AJ41: 其他
...

Sheet 装备位
B2: 装备位 | D2: 装备名 | G2: 装备效果 | W2: 重量/公斤 | Z2: 总重量/公斤
B3: 左手 | Z3: =SUM(W3:X92) -> 0
B6: 右手
B9: 头盔
B12: 项链
B15: 披风
B18: 盔甲
B21: 护腕/护臂
B24: 手套
B27: 腰带
B30: 鞋
B33: 戒指
B36: 戒指
B39: 饰品/护符
... B90: 其他

Sheet 购买记录
B2: 资源 | D2: 支线数（转化为D级支线数量） | J2: 分数 | N2: 经验数 | R2: 资源介绍
B3: 已获得 | D3: 2 | J3: 1650 | N3: 19 | R3: 五雷咒价格：D+500上清雷法第一层：练气 价格：D+600 上清雷法第二层：筑基 价格：12XP 掌心雷500 9 营养珠25 净水珠25
B5: 剩余 | D5: =D3-D7 -> 0 | J5: =J3-J7 -> 0 | N5: =N3-N7 -> -5
B7: 已使用 | D7: 2 | J7: 1650 | N7: 24

Sheet 成长记录
B2: 团名称/事件名 | F2: 支线数（转化为D级支线数量） | L2: 分数 | P2: 经验 | T2: 经历
B3: 总收入 | F3: =SUM(F7:K402) -> 0 | L3: =SUM(L7:O402) -> 0 | P3: =SUM(P7:S402)+天赋、缺陷和怪癖!D19 -> 6

Sheet 主动技能与书签整备
B2: 主动技能 | O2: 书签
D3: 技能名： | F3: 掌心雷 | O3: 资源名 | Q3: 是否携带 | S3: 支线数（转化为D级支线数量） | Y3: 分数 | AC3: 资源介绍
B4: 关键字：【雷】 专业：道术 威力值：2 价格：500 动作：标准动作 能耗：1 成分：语言，姿势 射程：20米 目标：一个目标 范围：无 持续：立即 描述：掌心雷攻击声音很大，相当于雷声的程度，这意味着方圆百里范围内所有具备听力的目标都会听到你的攻击。 效果：你以道术施法检定进行一次远程攻击，该次远程攻击的武器伤害为本道术的道术威力值，造成雷电严重伤害。 研发：你可以花费9XP进行研发，研发后获得以下效果： 本道术能耗变为1点，威力值提升为2点，之后本道术可以如常升阶。 然后你的本次攻击获得2点附加成功，射程改为20米。 | O4: 储存资源 | AC4: 左边填上你储存的资源总量，不包括购买书页的花费，储存的资源和买书页的花费仍需要写到购买记录中
O6: 剩余资源 | S6: =S4-S8 -> 0 | Y6: =Y4-Y8 -> 0
O8: 已使用 | S8: =SUMIF(Q:R,"是",S:X) -> 0 | Y8: =SUMIF(Q:R,"是",Y:AB) -> 0
Q10: 否
Q13: 否
Q16: 否
Q19: 否
D22: 技能名： | Q22: 否
B23: 五雷咒 关键字：【雷】 专业：道术 威力值：2 价格：D+500 动作：标准动作 能耗：1点道力 成分：姿势，语言，材料 射程：触及 目标：一个目标 范围：无 持续：立即 效果：你对目标造成15点雷电严重伤害，目标强韧豁免。
Q25: 否
Q28: 否
Q31: 否
Q34: 否
Q37: 否
Q40: 否
D41: 技能名：
Q43: 否
Q46: 否
Q49: 否
Q52: 否
Q55: 否
Q58: 否
D60: 技能名：
Q61: 否
Q64: 否
Q67: 否
Q70: 否
Q73: 否
Q76: 否
D79: 技能名： | Q79: 否
Q82: 否
Q85: 否
Q88: 否
Q91: 否
Q94: 否
Q97: 否
D98: 技能名：
Q100: 否
...

Sheet 天赋、缺陷和怪癖
B2: 怪癖段
B3: 怪癖名称 | D3: 怪癖内容 | W3: 抹除记录
B4: 口头禅 | D4: 口头禅 +2 XP 删除 战斗每轮1D10，出1则浪费迅捷动作。 | Z4: 备注：当你抹除一个怪癖时，不应删除其相关记录（尤其是怪癖名称），而是在抹除记录处写上任意文字，因此消耗的XP也无需在购买记录中再次记录
B13: 上瘾 | D13: 上瘾速度快，发作周期减半，禁断症状豁免-6DP。
B16: 爱出风头 | D16: 唬骗/易容/躲藏-3DP，战斗中总是第一个站出来
B19: 总XP | D19: =COUNTA(B4:C18)*2-COUNTA(W4:X18)*4 -> 6
B23: 缺陷 | Z23: 核算
B24: 缺陷名称 | D24: 缺陷点数 | F24: 缺陷内容 | Z24: 缺陷点数 | AC24: =SUM(D25:E54) -> 0
B25: 空气朋友 | F25: 所有人对你互动获2DP完美加值
Z27: 天赋点数 | AC27: =SUM(D58:E87) -> 0
B28: 养啥死啥 | F28: 非人宠物必死。
Z30: 结余 | AC30: =AC24-2*AC27 -> 0
B31: 音痴 | F31: 歌唱/演奏自动失败
B34: 好奇心 | F34: 不去探索未知则全检定-2DP。
B37: 机械白痴 | F37: 使用科技物品D10判故障。
B56: 天赋
B57: 天赋名称 | D57: 天赋点数 | F57: 天赋内容
B58: 夜视 | F58: 获得黑暗视觉。
B61: 幸运 | F61: 检定双判取高 (次数限制)
B64: 快速康复 | F64: 自然恢复速度翻倍。
B67: 灵感 | F67: 直觉检定+5附加，首次免投
B70: 战斗反射 | F70: 措手不及仍可用反射动作。
